2022-11-18 09:32:08,630 INFO    MainThread:21156 [internal.py:wandb_internal():63] W&B internal server running at pid: 21156
2022-11-18 09:32:08,631 DEBUG   HandlerThread:21156 [handler.py:handle_request():55] handle_request: check_version
2022-11-18 09:32:08,631 INFO    WriterThread:21156 [datastore.py:open_for_write():76] open: D:\code\yolov5-master\classify\wandb\run-20221118_093207-2fcsk8bj\run-2fcsk8bj.wandb
2022-11-18 09:32:08,637 DEBUG   SenderThread:21156 [sender.py:send():90] send: header
2022-11-18 09:32:08,637 DEBUG   SenderThread:21156 [sender.py:send():90] send: request
2022-11-18 09:32:08,637 DEBUG   SenderThread:21156 [sender.py:send_request():99] send_request: check_version
2022-11-18 09:32:08,638 DEBUG   Thread-8  :21156 [connectionpool.py:_new_conn():971] Starting new HTTPS connection (1): pypi.org:443
2022-11-18 09:32:09,167 DEBUG   Thread-8  :21156 [connectionpool.py:_make_request():452] https://pypi.org:443 "GET /pypi/wandb/json HTTP/1.1" 200 68841
2022-11-18 09:32:09,512 DEBUG   SenderThread:21156 [sender.py:send():90] send: run
2022-11-18 09:32:09,528 DEBUG   SenderThread:21156 [util.py:is_cygwin_git():315] Failed checking if running in CYGWIN due to: FileNotFoundError(2, '系统找不到指定的文件。', None, 2, None)
2022-11-18 09:32:09,529 DEBUG   SenderThread:21156 [git.py:repo():30] git repository is invalid
2022-11-18 09:32:09,532 DEBUG   SenderThread:21156 [connectionpool.py:_new_conn():971] Starting new HTTPS connection (1): api.wandb.ai:443
2022-11-18 09:32:10,049 DEBUG   SenderThread:21156 [connectionpool.py:_make_request():452] https://api.wandb.ai:443 "POST /graphql HTTP/1.1" 400 None
2022-11-18 09:32:10,050 ERROR   SenderThread:21156 [internal_api.py:execute():133] 400 response executing GraphQL.
2022-11-18 09:32:10,050 ERROR   SenderThread:21156 [internal_api.py:execute():134] {"errors":[{"message":"invalid project name ..\\runs\\train-cls, cannot contain character \"\\\"","path":["upsertBucket"]}],"data":{"upsertBucket":null}}
2022-11-18 09:32:10,522 INFO    WriterThread:21156 [datastore.py:close():257] close: D:\code\yolov5-master\classify\wandb\run-20221118_093207-2fcsk8bj\run-2fcsk8bj.wandb
2022-11-18 09:32:10,522 INFO    HandlerThread:21156 [handler.py:finish():271] shutting down handler
2022-11-18 09:32:10,634 ERROR   MainThread:21156 [internal.py:wandb_internal():129] Thread SenderThread:
Traceback (most recent call last):
  File "D:\ProgramData\Anaconda3\envs\yolov5\lib\site-packages\wandb\apis\normalize.py", line 24, in wrapper
    return func(*args, **kwargs)
  File "D:\ProgramData\Anaconda3\envs\yolov5\lib\site-packages\wandb\sdk\internal\internal_api.py", line 976, in upsert_run
    response = self.gql(mutation, variable_values=variable_values, **kwargs)
  File "D:\ProgramData\Anaconda3\envs\yolov5\lib\site-packages\wandb\old\retry.py", line 96, in __call__
    result = self._call_fn(*args, **kwargs)
  File "D:\ProgramData\Anaconda3\envs\yolov5\lib\site-packages\wandb\sdk\internal\internal_api.py", line 136, in execute
    six.reraise(*sys.exc_info())
  File "D:\ProgramData\Anaconda3\envs\yolov5\lib\site-packages\six.py", line 703, in reraise
    raise value
  File "D:\ProgramData\Anaconda3\envs\yolov5\lib\site-packages\wandb\sdk\internal\internal_api.py", line 130, in execute
    return self.client.execute(*args, **kwargs)
  File "D:\ProgramData\Anaconda3\envs\yolov5\lib\site-packages\wandb\vendor\gql-0.2.0\gql\client.py", line 52, in execute
    result = self._get_result(document, *args, **kwargs)
  File "D:\ProgramData\Anaconda3\envs\yolov5\lib\site-packages\wandb\vendor\gql-0.2.0\gql\client.py", line 60, in _get_result
    return self.transport.execute(document, *args, **kwargs)
  File "D:\ProgramData\Anaconda3\envs\yolov5\lib\site-packages\wandb\vendor\gql-0.2.0\gql\transport\requests.py", line 39, in execute
    request.raise_for_status()
  File "D:\ProgramData\Anaconda3\envs\yolov5\lib\site-packages\requests\models.py", line 943, in raise_for_status
    raise HTTPError(http_error_msg, response=self)
requests.exceptions.HTTPError: 400 Client Error: Bad Request for url: https://api.wandb.ai/graphql

During handling of the above exception, another exception occurred:

Traceback (most recent call last):
  File "D:\ProgramData\Anaconda3\envs\yolov5\lib\site-packages\wandb\sdk\internal\internal_util.py", line 33, in run
    self._run()
  File "D:\ProgramData\Anaconda3\envs\yolov5\lib\site-packages\wandb\sdk\internal\internal_util.py", line 60, in _run
    self._process(record)
  File "D:\ProgramData\Anaconda3\envs\yolov5\lib\site-packages\wandb\sdk\internal\internal.py", line 233, in _process
    self._sm.send(record)
  File "D:\ProgramData\Anaconda3\envs\yolov5\lib\site-packages\wandb\sdk\internal\sender.py", line 92, in send
    send_handler(record)
  File "D:\ProgramData\Anaconda3\envs\yolov5\lib\site-packages\wandb\sdk\internal\sender.py", line 379, in send_run
    self._init_run(run, config_dict)
  File "D:\ProgramData\Anaconda3\envs\yolov5\lib\site-packages\wandb\sdk\internal\sender.py", line 401, in _init_run
    server_run, inserted = self._api.upsert_run(
  File "D:\ProgramData\Anaconda3\envs\yolov5\lib\site-packages\wandb\apis\normalize.py", line 26, in wrapper
    raise CommError(err.response, err)
wandb.errors.error.CommError: <Response [400]>
2022-11-18 09:32:10,646 DEBUG   raven-sentry.BackgroundWorker:21156 [connectionpool.py:_new_conn():971] Starting new HTTPS connection (1): o151352.ingest.sentry.io:443
2022-11-18 09:32:10,978 DEBUG   raven-sentry.BackgroundWorker:21156 [connectionpool.py:_make_request():452] https://o151352.ingest.sentry.io:443 "POST /api/5288891/store/ HTTP/1.1" 200 41
2022-11-18 09:32:12,651 INFO    MainThread:21156 [internal.py:handle_exit():138] Internal process exited
